Workbook
Name ROI_период: Дашборд!$K$6
Name Банк_комиссия: Допущения!$C$11
Name Возврат_логистика: Допущения!$C$17
Name Выручка_итого: Дашборд!$B$6
Name Выручка_макс_год: ОПиУ!$D$55
Name Дата_начала: Допущения!$C$7
Name Деньги_конец: 'Денежный поток'!$D$75
Name Дней_в_месяце: Допущения!$C$24
Name Доставка_до_МП: Допущения!$C$16
Name Доставка_кг: Допущения!$C$13
Name Доставка_м3: Допущения!$C$14
Name Доставка_номер: Сценарии!$C$20
Name Доставка_список: Допущения!$A$76:$A$78
Name Доставка_способ: Допущения!$C$12
Name ДРР: Сценарии!$C$18
Name ДРР_база: Допущения!$C$18
Name Задержка_выплат_дн: Допущения!$C$23
Name Капитал_конец: Дашборд!$K$10
Name Капитал_старт: Допущения!$C$8
Name Комиссия_агента: Допущения!$C$10
Name Контроль_баланса: 'Денежный поток'!$D$84
Name Курс: Сценарии!$C$15
Name Курс_анализ: Чувствительность!$C$6
Name Курс_база: Допущения!$C$9
Name Лимит_НПД: Допущения!$C$33
Name Макс_разрыв: Дашборд!$E$10
Name Мин_налог_УСН15: Допущения!$C$32
Name Множитель_продаж: Сценарии!$C$17
Name Множитель_цены: Сценарии!$C$16
Name Налог_номер: Сценарии!$C$19
Name Налог_режим: Допущения!$C$27
Name Налог_список: Допущения!$A$29:$A$31
Name Объём_анализ: Чувствительность!$C$8
Name Окупаемость_мес: Дашборд!$H$10
Name Первый_разрыв: Дашборд!$E$11
Name Пик_вложений: Дашборд!$B$10
Name Порог_НДС_УСН: Допущения!$C$34
Name Пост_расходы: Допущения!$C$19
Name Рентабельность: Дашборд!$H$6
Name Срок_поставки: Допущения!$C$21
Name Ставка_НПД: Допущения!$C$31
Name Ставка_УСН15: Допущения!$C$30
Name Ставка_УСН6: Допущения!$C$29
Name Старт_расходы: Допущения!$C$20
Name Страх_запас: Допущения!$C$22
Name Сценарий_выбор: Сценарии!$C$5
Name Сценарий_номер: Сценарии!$C$21
Name Сценарий_ручной: Сценарии!$C$22
Name Тамож_оформление: Допущения!$C$15
Name Темп_продаж: Допущения!$C$56:$C$73
Name Упущено_шт: 'Закупки и склад'!$D$37
Name Цена_анализ: Чувствительность!$C$7
Name ЧП_итого: Дашборд!$E$6

Sheet Инструкция
B1: Финансовая модель: импорт автотоваров из Китая и продажа на маркетплейсах
B2: ДЕМО-ДАННЫЕ: все цифры — пример. Ставки пошлин, НДС, налогов и тарифы маркетплейса уточните под свой товар.
B4: Что считает модель
C5: • Закупку товара в Китае партиями, доставку, таможенные платежи и продажи на маркетплейсе на 18 месяцев вперёд.
C6: • Юнит-экономику каждого товара: полную себестоимость, прибыль, маржу, наценку, ROI и точку безубыточности.
C7: • Денежный поток: когда уходят деньги на закупку и когда приходят выплаты маркетплейса; показывает кассовый разрыв — месяцы, когда денег не хватает.
C8: • ОПиУ (прибыль и убытки) по месяцам с налогом по выбранному режиму.
C9: • Три сценария (базовый, пессимистичный, оптимистичный) и таблицы чувствительности к курсу юаня, цене и объёму продаж.
B11: Как пользоваться
B12: 1. Допущения | C12: Впишите свои данные в жёлтые ячейки: курс, тарифы доставки, товары (закупка в юанях, вес, объём, партия, цена продажи, плато продаж), ставки пошлины и НДС, комиссию и логистику маркетплейса, налоговый режим, стартовый капитал.
B13: 2. Темп продаж | C13: На листе «Допущения», раздел 4: сколько процентов от плато продаётся в каждом месяце. Первые месяцы товар едет — ставьте 0 %.
B14: 3. Сценарии | C14: Выберите сценарий в жёлтой ячейке листа «Сценарии». Проценты отклонений тоже можно менять.
B15: 4. Дашборд | C15: Главные цифры, предупреждения и графики. Красное — внимание: кассовый разрыв, убыточный товар.
B16: 5. Детали | C16: «Юнит-экономика» — каждая статья затрат на 1 шт; «Закупки и склад» — когда и сколько заказывать; «Денежный поток» и «ОПиУ» — по месяцам.
B17: 6. Чувствительность | C17: Сколько заработаете при другом курсе, цене или объёме — без ручного перебора.
B19: Цвета ячеек
B20: Ввод данных | C20: Жёлтая ячейка с синим шрифтом — меняйте. Только эти ячейки не защищены.
B21: Расчёт | C21: Белая ячейка — формула. Защищена от случайной правки.
B22: Итог | C22: Серая ячейка с жирным шрифтом — итоговая строка.
B23: Служебная | C23: Серый курсив — техническая ячейка модели, не меняйте.
B24: Внимание | C24: Красная заливка — кассовый разрыв, убыток, нехватка товара.
B25: Заказ | C25: Зелёная заливка на листе «Закупки и склад» — месяц заказа партии.
B27: Листы книги (нажмите, чтобы перейти)
B28: Дашборд | C28: главные показатели, предупреждения, графики; печатается на одну страницу
B29: Допущения | C29: все исходные данные — только здесь и на листе «Сценарии»
B30: Сценарии | C30: выбор сценария и сравнение трёх сценариев в одной таблице
B31: Юнит-экономика | C31: расчёт на 1 проданную единицу по каждому товару
B32: Закупки и склад | C32: спрос, продажи, остатки, товар в пути, заказы партиями
B33: Денежный поток | C33: поступления и выплаты по месяцам, остаток денег, кассовый разрыв, контроль баланса
B34: ОПиУ | C34: выручка, себестоимость, расходы, налог, чистая прибыль по месяцам
B35: Чувствительность | C35: таблицы «что если»: курс × цена, курс × объём
B37: Допущения и упрощения
C38: • Курс юаня постоянный внутри сценария; колебания курса — через сценарии и лист «Чувствительность».
C39: • Таможенная стоимость = товар + доставка до склада в РФ (консервативно). Пошлина — от таможенной стоимости, НДС на ввоз — от таможенной стоимости с пошлиной. НДС на ввоз включён в себестоимость: на УСН и НПД он к вычету не принимается.
C40: • Ставки пошлин, НДС, налогов, тарифы доставки и маркетплейса в книге — ПРИМЕР. Задайте свои: пошлина — по коду ТН ВЭД, комиссия — по категории товара на своей площадке.
C41: • Продажи = выкупы. Возвраты увеличивают логистику маркетплейса (доставка туда и обратно), возвращённый товар снова идёт в продажу.
C42: • Заказ поставщику: товар оплачивается в месяц заказа, доставка и таможня — в месяц поступления. Заказ кратен партии; продажи не превышают остаток на складе.
C43: • Налог: база — данные ОПиУ по месяцу продажи (упрощение кассового метода УСН). УСН платится поквартально в месяце после квартала, НПД — в следующем месяце. Взносы ИП и НДС на УСН при превышении порога не считаются — дашборд предупреждает о пороге.
C44: • Окупаемость — месяц, начиная с которого накопленный денежный поток больше не уходит в минус. ROI = чистая прибыль / пик вложенных денег.
B46: Защита и проверка
...

Sheet Дашборд
B1: Финансовая модель: импорт автотоваров из Китая и продажа на маркетплейсах
B2: Сценарий: | C2: =Сценарий_выбор -> Базовый | E2: Налог: | F2: =Налог_режим -> УСН 6% | H2: Период: | I2: =Дата_начала -> 46327 | K2: по | L2: ='Денежный поток'!W$5 -> 46844
B3: ДЕМО-ДАННЫЕ: все цифры — пример. Ставки пошлин, НДС, налогов и тарифы маркетплейса уточните под свой товар.
B5: ВЫРУЧКА ЗА ПЕРИОД | E5: ЧИСТАЯ ПРИБЫЛЬ | H5: РЕНТАБЕЛЬНОСТЬ ПРОДАЖ | K5: ROI НА ВЛОЖЕННЫЕ ДЕНЬГИ
B6: =ОПиУ!D8 -> 24404970 | E6: =ОПиУ!D46 -> 3052575.5 | H6: =IFERROR(ЧП_итого/Выручка_итого,0) -> 0.12508007 | K6: =IFERROR(ЧП_итого/Пик_вложений,0) -> 1.2730327
B7: выкупы × цена, 18 мес | E7: после налога, 18 мес | H7: чистая прибыль / выручка | K7: чистая прибыль / пик вложений
B9: ПОТРЕБНОСТЬ В ДЕНЬГАХ | E9: МАКС. КАССОВЫЙ РАЗРЫВ | H9: ОКУПАЕМОСТЬ ВЛОЖЕНИЙ | K9: КАПИТАЛ НА КОНЕЦ
B10: =MAX(0,-MIN('Денежный поток'!$F$68:$W$68)) -> 2397876.7 | E10: =MAX('Денежный поток'!$F$66:$W$66) -> 397876.69 | H10: =IFERROR(MATCH(TRUE,'Денежный поток'!$F$70:$W$70,0),"более "&MAX('Денежный поток'!$F$4:$W$4)) -> 16 | K10: ='Денежный поток'!D80 -> 5052575.5
B11: пик вложенных денег | E11: =IFERROR(INDEX('Денежный поток'!$F$5:$W$5,MATCH(TRUE,'Денежный поток'!$F$67:$W$67,0)),"нет") -> 46419 | H11: месяц, с которого деньги не уходят в минус | K11: деньги + товар + дебиторка − налог
B13: =IF(Макс_разрыв>0,"⚠ Кассовый разрыв: в худший месяц не хватает "&FIXED(Макс_разрыв,0)&" ₽. Нужен доп. капитал, меньшие партии или отсрочка оплаты поставщику.","✓ Денег хватает на весь период: кассового разрыва нет.") -> ⚠ Кассовый разрыв: в худший месяц не хватает 397 877 ₽. Нужен доп. капитал, меньшие партии или отсрочка оплаты поставщику.
B14: =IF(COUNTIF('Юнит-экономика'!$C$31:$G$31,"<0")>0,"⚠ Есть товары с убытком на каждой продаже — см. таблицу ниже. ","")&IF(Упущено_шт>0,"⚠ Упущено продаж из-за нехватки товара: "&FIXED(Упущено_шт,0)&" шт. ","")&IF(AND(Налог_номер<3,Выручка_макс_год>Порог_НДС_УСН),"⚠ Выручка за календарный год выше порога НДС для УСН — уточните НДС у бухгалтера. ","")&IF(Налог_номер=3,"⚠ НПД не применяется при перепродаже товаров (422-ФЗ, ст. 4) — режим только для сравнения. ","")&IF(AND(Налог_номер=3,Выручка_макс_год>Лимит_НПД),"⚠ Доход выше лимита НПД. ","")
B15: ="Контроль баланса модели: "&Контроль_баланса&" • остаток денег на конец: "&FIXED(Деньги_конец,0)&" ₽" -> Контроль баланса модели: OK • остаток денег на конец: 2 532 186 ₽
B17: Товар | D17: Цена, ₽ | E17: Себест. на складе МП, ₽ | F17: Прибыль на 1 шт, ₽ | G17: Маржа | H17: ROI на 1 шт | I17: Точка безубыт., шт/мес | J17: План на плато, шт/мес | K17: Продано за период, шт | L17: Выручка за период, ₽ | M17: Упущено, шт
B18: ='Юнит-экономика'!C$4 -> Органайзер в багажник | D18: ='Юнит-экономика'!$C$6 -> 2490 | E18: ='Юнит-экономика'!$C$20 -> 1026.7768 | F18: ='Юнит-экономика'!$C$31 -> 498.20215 | G18: ='Юнит-экономика'!$C$32 -> 0.20008118 | H18: ='Юнит-экономика'!$C$34 -> 0.48520978 | I18: ='Юнит-экономика'!$C$39 -> 21.512512 | J18: ='Юнит-экономика'!$C$36 -> 140 | K18: ='Закупки и склад'!D24 -> 2100 | L18: =ОПиУ!D9 -> 5229000 | M18: ='Закупки и склад'!D32 -> 0
B19: ='Юнит-экономика'!D$4 -> Автопылесос беспроводной | D19: ='Юнит-экономика'!$D$6 -> 2990 | E19: ='Юнит-экономика'!$D$20 -> 1313.3625 | F19: ='Юнит-экономика'!$D$31 -> 617.66355 | G19: ='Юнит-экономика'!$D$32 -> 0.20657644 | H19: ='Юнит-экономика'!$D$34 -> 0.47029174 | I19: ='Юнит-экономика'!$D$39 -> 17.859521 | J19: ='Юнит-экономика'!$D$36 -> 120 | K19: ='Закупки и склад'!D25 -> 1800 | L19: =ОПиУ!D10 -> 5382000 | M19: ='Закупки и склад'!D33 -> 0
B20: ='Юнит-экономика'!E$4 -> Держатель телефона MagSafe | D20: ='Юнит-экономика'!$E$6 -> 1290 | E20: ='Юнит-экономика'!$E$20 -> 473.76547 | F20: ='Юнит-экономика'!$E$31 -> 298.60228 | G20: ='Юнит-экономика'!$E$32 -> 0.23147463 | H20: ='Юнит-экономика'!$E$34 -> 0.63027446 | I20: ='Юнит-экономика'!$E$39 -> 34.533396 | J20: ='Юнит-экономика'!$E$36 -> 260 | K20: ='Закупки и склад'!D26 -> 3900 | L20: =ОПиУ!D11 -> 5031000 | M20: ='Закупки и склад'!D34 -> 0
B21: ='Юнит-экономика'!F$4 -> Чехлы на сиденья, комплект | D21: ='Юнит-экономика'!$F$6 -> 4490 | E21: ='Юнит-экономика'!$F$20 -> 2705.811 | F21: ='Юнит-экономика'!$F$31 -> 52.033444 | G21: ='Юнит-экономика'!$F$32 -> 0.01158874 | H21: ='Юнит-экономика'!$F$34 -> 0.019230258 | I21: ='Юнит-экономика'!$F$39 -> 159.17848 | J21: ='Юнит-экономика'!$F$36 -> 60 | K21: ='Закупки и склад'!D27 -> 900 | L21: =ОПиУ!D12 -> 4041000 | M21: ='Закупки и склад'!D35 -> 0
B22: ='Юнит-экономика'!G$4 -> Видеорегистратор Wi-Fi | D22: ='Юнит-экономика'!$G$6 -> 3490 | E22: ='Юнит-экономика'!$G$20 -> 1710.5292 | F22: ='Юнит-экономика'!$G$31 -> 604.71366 | G22: ='Юнит-экономика'!$G$32 -> 0.17327039 | H22: ='Юнит-экономика'!$G$34 -> 0.35352431 | I22: ='Юнит-экономика'!$G$39 -> 15.96936 | J22: ='Юнит-экономика'!$G$36 -> 90 | K22: ='Закупки и склад'!D28 -> 1353 | L22: =ОПиУ!D13 -> 4721970 | M22: ='Закупки и склад'!D36 -> 0
B23: Итого | K23: =SUM(K18:K22) -> 10053 | L23: =SUM(L18:L22) -> 24404970 | M23: =SUM(M18:M22) -> 0
B25: Остаток денег на счёте, ₽ | F25: Выручка и чистая прибыль по месяцам, ₽ | J25: Из чего складывается цена, ₽ на 1 шт

Sheet Допущения
A1: Допущения — ввод данных
A2: Жёлтые ячейки — ввод (можно менять). Остальные ячейки считаются формулами и защищены. Ставки пошлин, НДС, налогов и тарифы маркетплейса — параметры: уточните их под свой товар.
A3: ДЕМО-ДАННЫЕ: все цифры — пример. Ставки пошлин, НДС, налогов и тарифы маркетплейса уточните под свой товар.
A5: 1. Общие параметры
A6: Параметр | B6: Ед. | C6: Значение | D6: Комментарий
A7: Первый месяц модели (месяц первой оплаты поставщику) | B7: дата | C7: 46327 | D7: Горизонт модели — 18 месяцев с этой даты
A8: Стартовый капитал (свои деньги на счёте) | B8: ₽ | C8: 2000000 | D8: Если остаток денег уходит в минус — это кассовый разрыв
A9: Курс юаня, базовый | B9: ₽ за ¥ | C9: 12 | D9: Сценарии меняют курс относительно этого значения
A10: Комиссия агента / байера в Китае | B10: % товара | C10: 0.03 | D10: Поиск поставщика, выкуп, контроль качества — по договору с агентом
A11: Банк и конвертация при оплате поставщику | B11: % | C11: 0.015 | D11: От суммы «товар + агент»; платёжный агент или банк
A12: Как считать доставку из Китая | B12: список | C12: по большему | D12: по весу / по объёму / по большему из двух — как считает ваш перевозчик
A13: Доставка Китай → склад в РФ, тариф по весу | B13: ₽/кг | C13: 220 | D13: Уточните у карго / экспедитора
A14: Доставка Китай → склад в РФ, тариф по объёму | B14: ₽/м³ | C14: 24000 | D14: Уточните у карго / экспедитора
A15: Таможенное оформление (брокер, сборы) на одну партию товара | B15: ₽/партию | C15: 8000 | D15: Уточните у таможенного брокера. Если карго «под ключ» — 0, а пошлину и НДС на ввоз включите в тариф доставки
A16: Доставка со склада в РФ до склада маркетплейса | B16: ₽/кг | C16: 25 | D16: Фулфилмент / транспортная компания
A17: Обратная логистика маркетплейса за один возврат | B17: ₽/шт | C17: 50 | D17: Уточните по тарифам своей площадки
A18: Реклама на маркетплейсе (доля рекламных расходов) | B18: % выручки | C18: 0.08 | D18: Сценарии добавляют или убавляют п.п.
A19: Постоянные расходы (бухгалтерия, сервисы, персонал) | B19: ₽/мес | C19: 50000 | D19: Каждый месяц с первого
A20: Разовые стартовые расходы (образцы, фото, карточки) | B20: ₽ | C20: 60000 | D20: Списываются в первом месяце
A21: Срок поставки: от оплаты поставщику до склада маркетплейса | B21: мес | C21: 2 | D21: Целое число 1–6. Товар поступает в продажу через столько месяцев после заказа
A22: Страховой запас | B22: мес продаж | C22: 1 | D22: Целое число 0–3. Сколько месяцев продаж держать сверх срока поставки
A23: Задержка выплат маркетплейса после продажи | B23: дней | C23: 14 | D23: 0–120 дней. Дробная часть месяца делится между месяцами
A24: Дней в месяце (для пересчёта задержки выплат) | B24: дней | C24: 30 | D24: Обычно 30
A26: 2. Налоги (ставки — параметры: проверьте свой режим и регион)
A27: Налоговый режим | B27: список | C27: УСН 6% | D27: УСН 6 % — с доходов; УСН 15 % — с доходов минус расходы; НПД — для сравнения
A28: Режим | B28: Ед. | C28: Ставка | D28: Комментарий
A29: УСН 6% | B29: % | C29: 0.06 | D29: Налог с выручки. Базовая ставка; регион может установить ниже — уточните
A30: УСН 15% | B30: % | C30: 0.15 | D30: Налог с разницы «доходы − расходы», считается нарастающим итогом с начала года
A31: НПД | B31: % | C31: 0.06 | D31: Внимание: НПД не применяется при перепродаже товаров (422-ФЗ, ст. 4) — режим оставлен для сравнения
A32: Минимальный налог при УСН 15 % | B32: % доходов | C32: 0.01 | D32: В модели — нарастающим итогом с начала года (консервативно)
A33: Лимит дохода для НПД | B33: ₽/год | C33: 2400000 | D33: Параметр для предупреждения на дашборде — проверьте актуальный лимит
A34: Порог доходов, выше которого УСН платит НДС | B34: ₽/год | C34: 20000000 | D34: Пример — проверьте порог на свой год. НДС на УСН модель не считает, только предупреждает о превышении
A36: 3. Товары (SKU): одна колонка — один товар
A37: Параметр | B37: Ед. | C37: Товар 1 | D37: Товар 2 | E37: Товар 3 | F37: Товар 4 | G37: Товар 5 | H37: Комментарий
A38: Наименование | C38: Органайзер в багажник | D38: Автопылесос беспроводной | E38: Держатель телефона MagSafe | F38: Чехлы на сиденья, комплект | G38: Видеорегистратор Wi-Fi | H38: Короткое название — попадёт в отчёты и графики
A39: Закупочная цена у поставщика | B39: ¥/шт | C39: 32 | D39: 58 | E39: 22 | F39: 105 | G39: 98 | H39: Цена фабрики (EXW/FOB) за единицу
A40: Вес брутто с упаковкой | B40: кг/шт | C40: 1.3 | D40: 1 | E40: 0.3 | F40: 2.6 | G40: 0.4 | H40: Для тарифа доставки по весу
A41: Объём с упаковкой | B41: м³/шт | C41: 0.012 | D41: 0.005 | E41: 0.0012 | F41: 0.018 | G41: 0.0018 | H41: Длина × ширина × высота коробки, м
A42: Партия закупки (кратность заказа) | B42: шт | C42: 200 | D42: 150 | E42: 300 | F42: 100 | G42: 100 | H42: Минимальный заказ у поставщика; модель заказывает кратно партии
A43: Цена продажи на маркетплейсе | B43: ₽ | C43: 2490 | D43: 2990 | E43: 1290 | F43: 4490 | G43: 3490 | H43: Цена, которую платит покупатель (после скидок)
...

Sheet Сценарии
A1: Сценарии
A2: Выберите сценарий в жёлтой ячейке — пересчитается вся книга. Базовый = значения листа «Допущения»; остальные сценарии — отклонения от них.
A3: ДЕМО-ДАННЫЕ: все цифры — пример. Ставки пошлин, НДС, налогов и тарифы маркетплейса уточните под свой товар.
A5: Активный сценарий | C5: Базовый
A7: Отклонения от базовых допущений
A8: Параметр | B8: Ед. | C8: Базовый | D8: Пессимистичный | E8: Оптимистичный | F8: Действует сейчас
A9: Курс юаня | B9: % к базе | C9: 0 | D9: 0.15 | E9: -0.05 | F9: =INDEX($C9:$E9,Сценарий_номер) -> 0
A10: Цена продажи | B10: % к базе | C10: 0 | D10: -0.08 | E10: 0.05 | F10: =INDEX($C10:$E10,Сценарий_номер) -> 0
A11: Темп продаж | B11: % к базе | C11: 0 | D11: -0.25 | E11: 0.2 | F11: =INDEX($C11:$E11,Сценарий_номер) -> 0
A12: Реклама (ДРР) | B12: п.п. | C12: 0 | D12: 0.03 | E12: -0.02 | F12: =INDEX($C12:$E12,Сценарий_номер) -> 0
A14: Действующие значения (их использует вся модель)
A15: Курс юаня | B15: ₽ за ¥ | C15: =IF(Курс_анализ>0,Курс_анализ,Курс_база*(1+$F$9)) -> 12
A16: Множитель цены продажи | B16: × | C16: =(1+$F$10)*(1+Цена_анализ) -> 1
A17: Множитель темпа продаж | B17: × | C17: =(1+$F$11)*(1+Объём_анализ) -> 1
A18: Реклама, доля выручки | B18: % | C18: =MAX(0,ДРР_база+$F$12) -> 0.08
A19: Налоговый режим (номер в списке) | B19: № | C19: =MATCH(Налог_режим,Налог_список,0) -> 1
A20: Способ расчёта доставки (номер в списке) | B20: № | C20: =MATCH(Доставка_способ,Доставка_список,0) -> 3
A21: Номер активного сценария | B21: № | C21: =IF(Сценарий_ручной>0,Сценарий_ручной,MATCH(Сценарий_выбор,$C$8:$E$8,0)) -> 1
A22: Служебная: номер сценария для таблицы сравнения (держать 0) | C22: 0
A24: Сравнение сценариев — все три сразу (таблица данных Excel, считается автоматически)
A25: Сценарий | B25: № | C25: Чистая прибыль за 18 мес, ₽ | D25: Выручка за 18 мес, ₽ | E25: Рентабельность продаж | F25: ROI на вложенные деньги | G25: Потребность в деньгах (пик), ₽ | H25: Макс. кассовый разрыв, ₽ | I25: Окупаемость, мес
A26: Текущий расчёт (активный сценарий) | B26: =Сценарий_номер -> 1 | C26: =ЧП_итого -> 3052575.5 | D26: =Выручка_итого -> 24404970 | E26: =Рентабельность -> 0.12508007 | F26: =ROI_период -> 1.2730327 | G26: =Пик_вложений -> 2397876.7 | H26: =Макс_разрыв -> 397876.69 | I26: =Окупаемость_мес -> 16
A27: =INDEX($C$8:$E$8,B27) -> Базовый | B27: 1 | C27: 3052575.5 | D27: 24404970 | E27: 0.12508007 | F27: 1.2730327 | G27: 2397876.7 | H27: 397876.69 | I27: 16
A28: =INDEX($C$8:$E$8,B28) -> Пессимистичный | B28: 2 | C28: -343308.82 | D28: 16862864 | E28: -0.020358868 | F28: -0.11410835 | G28: 3008621.3 | H28: 1008621.3 | I28: более 18
A29: =INDEX($C$8:$E$8,B29) -> Оптимистичный | B29: 3 | C29: 5941978 | D29: 30733720 | E29: 0.19333741 | F29: 2.5329487 | G29: 2345873.8 | H29: 345873.75 | I29: 13
A31: Таблица пересчитывает всю модель для каждого сценария. Если в Excel включён режим «Автоматически, кроме таблиц данных», нажмите F9.

Sheet Юнит-экономика
A1: Юнит-экономика: на 1 проданную единицу
A2: ДЕМО-ДАННЫЕ: все цифры — пример. Ставки пошлин, НДС, налогов и тарифы маркетплейса уточните под свой товар.
A3: ="Сценарий: "&Сценарий_выбор&" • курс "&FIXED(Курс,2)&" ₽/¥ • налог: "&Налог_режим -> Сценарий: Базовый • курс 12,00 ₽/¥ • налог: УСН 6%
A4: Показатель | B4: Ед. | C4: =""&Допущения!$C$38 -> Органайзер в багажник | D4: =""&Допущения!$D$38 -> Автопылесос беспроводной | E4: =""&Допущения!$E$38 -> Держатель телефона MagSafe | F4: =""&Допущения!$F$38 -> Чехлы на сиденья, комплект | G4: =""&Допущения!$G$38 -> Видеорегистратор Wi-Fi
A5: Цена
A6: Цена продажи с учётом сценария | B6: ₽ | C6: =Допущения!$C$43*Множитель_цены -> 2490 | D6: =Допущения!$D$43*Множитель_цены -> 2990 | E6: =Допущения!$E$43*Множитель_цены -> 1290 | F6: =Допущения!$F$43*Множитель_цены -> 4490 | G6: =Допущения!$G$43*Множитель_цены -> 3490
A7: Себестоимость 1 шт до склада маркетплейса
A8: Закупочная цена | B8: ¥ | C8: =Допущения!$C$39 -> 32 | D8: =Допущения!$D$39 -> 58 | E8: =Допущения!$E$39 -> 22 | F8: =Допущения!$F$39 -> 105 | G8: =Допущения!$G$39 -> 98
A9: Курс юаня | B9: ₽/¥ | C9: =Курс -> 12 | D9: =Курс -> 12 | E9: =Курс -> 12 | F9: =Курс -> 12 | G9: =Курс -> 12
A10: Товар | B10: ₽ | C10: =C8*C9 -> 384 | D10: =D8*D9 -> 696 | E10: =E8*E9 -> 264 | F10: =F8*F9 -> 1260 | G10: =G8*G9 -> 1176
A11: Комиссия агента | B11: ₽ | C11: =C10*Комиссия_агента -> 11.52 | D11: =D10*Комиссия_агента -> 20.88 | E11: =E10*Комиссия_агента -> 7.92 | F11: =F10*Комиссия_агента -> 37.8 | G11: =G10*Комиссия_агента -> 35.28
A12: Банк и конвертация | B12: ₽ | C12: =(C10+C11)*Банк_комиссия -> 5.9328 | D12: =(D10+D11)*Банк_комиссия -> 10.7532 | E12: =(E10+E11)*Банк_комиссия -> 4.0788 | F12: =(F10+F11)*Банк_комиссия -> 19.467 | G12: =(G10+G11)*Банк_комиссия -> 18.1692
A13: Доставка Китай → РФ | B13: ₽ | C13: =CHOOSE(Доставка_номер,Допущения!$C$40*Доставка_кг,Допущения!$C$41*Доставка_м3,MAX(Допущения!$C$40*Доставка_кг,Допущения!$C$41*Доставка_м3)) -> 288 | D13: =CHOOSE(Доставка_номер,Допущения!$D$40*Доставка_кг,Допущения!$D$41*Доставка_м3,MAX(Допущения!$D$40*Доставка_кг,Допущения!$D$41*Доставка_м3)) -> 220 | E13: =CHOOSE(Доставка_номер,Допущения!$E$40*Доставка_кг,Допущения!$E$41*Доставка_м3,MAX(Допущения!$E$40*Доставка_кг,Допущения!$E$41*Доставка_м3)) -> 66 | F13: =CHOOSE(Доставка_номер,Допущения!$F$40*Доставка_кг,Допущения!$F$41*Доставка_м3,MAX(Допущения!$F$40*Доставка_кг,Допущения!$F$41*Доставка_м3)) -> 572 | G13: =CHOOSE(Доставка_номер,Допущения!$G$40*Доставка_кг,Допущения!$G$41*Доставка_м3,MAX(Допущения!$G$40*Доставка_кг,Допущения!$G$41*Доставка_м3)) -> 88
A14: Таможенная стоимость (товар + доставка), справочно | B14: ₽ | C14: =C10+C13 -> 672 | D14: =D10+D13 -> 916 | E14: =E10+E13 -> 330 | F14: =F10+F13 -> 1832 | G14: =G10+G13 -> 1264
A15: Пошлина | B15: ₽ | C15: =C14*Допущения!$C$46 -> 67.2 | D15: =D14*Допущения!$D$46 -> 45.8 | E15: =E14*Допущения!$E$46 -> 0 | F15: =F14*Допущения!$F$46 -> 183.2 | G15: =G14*Допущения!$G$46 -> 0
A16: НДС на ввоз | B16: ₽ | C16: =(C14+C15)*Допущения!$C$47 -> 162.624 | D16: =(D14+D15)*Допущения!$D$47 -> 211.596 | E16: =(E14+E15)*Допущения!$E$47 -> 72.6 | F16: =(F14+F15)*Допущения!$F$47 -> 443.344 | G16: =(G14+G15)*Допущения!$G$47 -> 278.08
A17: Таможенное оформление на 1 шт | B17: ₽ | C17: =IFERROR(Тамож_оформление/Допущения!$C$42,0) -> 40 | D17: =IFERROR(Тамож_оформление/Допущения!$D$42,0) -> 53.333333 | E17: =IFERROR(Тамож_оформление/Допущения!$E$42,0) -> 26.666667 | F17: =IFERROR(Тамож_оформление/Допущения!$F$42,0) -> 80 | G17: =IFERROR(Тамож_оформление/Допущения!$G$42,0) -> 80
A18: Упаковка и маркировка | B18: ₽ | C18: =Допущения!$C$49 -> 35 | D18: =Допущения!$D$49 -> 30 | E18: =Допущения!$E$49 -> 25 | F18: =Допущения!$F$49 -> 45 | G18: =Допущения!$G$49 -> 25
A19: Доставка до склада маркетплейса | B19: ₽ | C19: =Допущения!$C$40*Доставка_до_МП -> 32.5 | D19: =Допущения!$D$40*Доставка_до_МП -> 25 | E19: =Допущения!$E$40*Доставка_до_МП -> 7.5 | F19: =Допущения!$F$40*Доставка_до_МП -> 65 | G19: =Допущения!$G$40*Доставка_до_МП -> 10
A20: Себестоимость 1 шт на складе маркетплейса | B20: ₽ | C20: =C10+C11+C12+C13+C15+C16+C17+C18+C19 -> 1026.7768 | D20: =D10+D11+D12+D13+D15+D16+D17+D18+D19 -> 1313.3625 | E20: =E10+E11+E12+E13+E15+E16+E17+E18+E19 -> 473.76547 | F20: =F10+F11+F12+F13+F15+F16+F17+F18+F19 -> 2705.811 | G20: =G10+G11+G12+G13+G15+G16+G17+G18+G19 -> 1710.5292
A21: в т.ч. платится при заказе (товар, агент, банк) | B21: ₽ | C21: =C10+C11+C12 -> 401.4528 | D21: =D10+D11+D12 -> 727.6332 | E21: =E10+E11+E12 -> 275.9988 | F21: =F10+F11+F12 -> 1317.267 | G21: =G10+G11+G12 -> 1229.4492
A22: в т.ч. платится при поступлении (доставка, таможня, подготовка) | B22: ₽ | C22: =C20-C21 -> 625.324 | D22: =D20-D21 -> 585.72933 | E22: =E20-E21 -> 197.76667 | F22: =F20-F21 -> 1388.544 | G22: =G20-G21 -> 481.08
A23: Расходы на продажу, на 1 выкупленную шт
A24: Комиссия маркетплейса | B24: ₽ | C24: =C6*Допущения!$C$50 -> 498 | D24: =D6*Допущения!$D$50 -> 538.2 | E24: =E6*Допущения!$E$50 -> 258 | F24: =F6*Допущения!$F$50 -> 898 | G24: =G6*Допущения!$G$50 -> 593.3
A25: Логистика маркетплейса с учётом возвратов | B25: ₽ | C25: =(Допущения!$C$51+Допущения!$C$52*Возврат_логистика)/(1-Допущения!$C$52) -> 118.42105 | D25: =(Допущения!$D$51+Допущения!$D$52*Возврат_логистика)/(1-Допущения!$D$52) -> 102.17391 | E25: =(Допущения!$E$51+Допущения!$E$52*Возврат_логистика)/(1-Допущения!$E$52) -> 79.032258 | F25: =(Допущения!$F$51+Допущения!$F$52*Возврат_логистика)/(1-Допущения!$F$52) -> 205.55556 | G25: =(Допущения!$G$51+Допущения!$G$52*Возврат_логистика)/(1-Допущения!$G$52) -> 92.857143
A26: Реклама | B26: ₽ | C26: =C6*ДРР -> 199.2 | D26: =D6*ДРР -> 239.2 | E26: =E6*ДРР -> 103.2 | F26: =F6*ДРР -> 359.2 | G26: =G6*ДРР -> 279.2
A27: Прибыль до налога | B27: ₽ | C27: =C6-C20-C24-C25-C26 -> 647.60215 | D27: =D6-D20-D24-D25-D26 -> 797.06355 | E27: =E6-E20-E24-E25-E26 -> 376.00228 | F27: =F6-F20-F24-F25-F26 -> 321.43344 | G27: =G6-G20-G24-G25-G26 -> 814.11366
A28: Налог | B28: ₽ | C28: =CHOOSE(Налог_номер,C6*Ставка_УСН6,MAX(C27*Ставка_УСН15,C6*Мин_налог_УСН15),C6*Ставка_НПД) -> 149.4 | D28: =CHOOSE(Налог_номер,D6*Ставка_УСН6,MAX(D27*Ставка_УСН15,D6*Мин_налог_УСН15),D6*Ставка_НПД) -> 179.4 | E28: =CHOOSE(Налог_номер,E6*Ставка_УСН6,MAX(E27*Ставка_УСН15,E6*Мин_налог_УСН15),E6*Ставка_НПД) -> 77.4 | F28: =CHOOSE(Налог_номер,F6*Ставка_УСН6,MAX(F27*Ставка_УСН15,F6*Мин_налог_УСН15),F6*Ставка_НПД) -> 269.4 | G28: =CHOOSE(Налог_номер,G6*Ставка_УСН6,MAX(G27*Ставка_УСН15,G6*Мин_налог_УСН15),G6*Ставка_НПД) -> 209.4
A29: Полная себестоимость продажи | B29: ₽ | C29: =C20+C24+C25+C26+C28 -> 1991.7979 | D29: =D20+D24+D25+D26+D28 -> 2372.3364 | E29: =E20+E24+E25+E26+E28 -> 991.39772 | F29: =F20+F24+F25+F26+F28 -> 4437.9666 | G29: =G20+G24+G25+G26+G28 -> 2885.2863
A30: Результат на 1 шт
A31: Прибыль на 1 шт | B31: ₽ | C31: =C6-C29 -> 498.20215 | D31: =D6-D29 -> 617.66355 | E31: =E6-E29 -> 298.60228 | F31: =F6-F29 -> 52.033444 | G31: =G6-G29 -> 604.71366
A32: Маржа (прибыль / цена) | B32: % | C32: =IFERROR(C31/C6,0) -> 0.20008118 | D32: =IFERROR(D31/D6,0) -> 0.20657644 | E32: =IFERROR(E31/E6,0) -> 0.23147463 | F32: =IFERROR(F31/F6,0) -> 0.01158874 | G32: =IFERROR(G31/G6,0) -> 0.17327039
A33: Наценка к себестоимости на складе МП | B33: % | C33: =IFERROR((C6-C20)/C20,0) -> 1.4250645 | D33: =IFERROR((D6-D20)/D20,0) -> 1.2765991 | E33: =IFERROR((E6-E20)/E20,0) -> 1.7228663 | F33: =IFERROR((F6-F20)/F20,0) -> 0.65939158 | G33: =IFERROR((G6-G20)/G20,0) -> 1.0403043
A34: ROI на вложенный рубль (прибыль / себестоимость) | B34: % | C34: =IFERROR(C31/C20,0) -> 0.48520978 | D34: =IFERROR(D31/D20,0) -> 0.47029174 | E34: =IFERROR(E31/E20,0) -> 0.63027446 | F34: =IFERROR(F31/F20,0) -> 0.019230258 | G34: =IFERROR(G31/G20,0) -> 0.35352431
A35: Безубыточность
A36: План продаж на плато с учётом сценария | B36: шт/мес | C36: =Допущения!$C$44*Множитель_продаж -> 140 | D36: =Допущения!$D$44*Множитель_продаж -> 120 | E36: =Допущения!$E$44*Множитель_продаж -> 260 | F36: =Допущения!$F$44*Множитель_продаж -> 60 | G36: =Допущения!$G$44*Множитель_продаж -> 90
A37: Доля товара в выручке на плато | B37: % | C37: =IFERROR(C6*Допущения!$C$44/SUMPRODUCT($C$6:$G$6,Допущения!$C$44:$G$44),0) -> 0.2143516 | D37: =IFERROR(D6*Допущения!$D$44/SUMPRODUCT($C$6:$G$6,Допущения!$C$44:$G$44),0) -> 0.2206235 | E37: =IFERROR(E6*Допущения!$E$44/SUMPRODUCT($C$6:$G$6,Допущения!$C$44:$G$44),0) -> 0.20623501 | F37: =IFERROR(F6*Допущения!$F$44/SUMPRODUCT($C$6:$G$6,Допущения!$C$44:$G$44),0) -> 0.16565209 | G37: =IFERROR(G6*Допущения!$G$44/SUMPRODUCT($C$6:$G$6,Допущения!$C$44:$G$44),0) -> 0.1931378
A38: Постоянные расходы, приходящиеся на товар | B38: ₽/мес | C38: =Пост_расходы*C37 -> 10717.58 | D38: =Пост_расходы*D37 -> 11031.175 | E38: =Пост_расходы*E37 -> 10311.751 | F38: =Пост_расходы*F37 -> 8282.6047 | G38: =Пост_расходы*G37 -> 9656.8899
A39: Точка безубыточности (покрыть свои постоянные расходы) | B39: шт/мес | C39: =IF(C31>0,C38/C31,"убыток на ед.") -> 21.512512 | D39: =IF(D31>0,D38/D31,"убыток на ед.") -> 17.859521 | E39: =IF(E31>0,E38/E31,"убыток на ед.") -> 34.533396 | F39: =IF(F31>0,F38/F31,"убыток на ед.") -> 159.17848 | G39: =IF(G31>0,G38/G31,"убыток на ед.") -> 15.96936
A40: Сертификация окупается за | B40: шт | C40: =IF(C31>0,Допущения!$C$48/C31,"—") -> 40.144347 | D40: =IF(D31>0,Допущения!$D$48/D31,"—") -> 72.855197 | E40: =IF(E31>0,Допущения!$E$48/E31,"—") -> 133.95745 | F40: =IF(F31>0,Допущения!$F$48/F31,"—") -> 384.36817 | G40: =IF(G31>0,Допущения!$G$48/G31,"—") -> 82.683762

Sheet Закупки и склад
A1: Закупки и склад: штуки по месяцам
A2: Логика заказа: каждый месяц модель проверяет остаток + товар в пути. Если их не хватает на продажи за срок поставки + страховой запас — заказывает партии (кратно партии SKU). Заказ приходит через «Срок поставки» месяцев.
A3: ДЕМО-ДАННЫЕ: все цифры — пример. Ставки пошлин, НДС, налогов и тарифы маркетплейса уточните под свой товар.
A4: Месяц № | F4: =COLUMN()-COLUMN($E$4) -> 1 | G4: =COLUMN()-COLUMN($E$4) -> 2 | H4: =COLUMN()-COLUMN($E$4) -> 3 | I4: =COLUMN()-COLUMN($E$4) -> 4 | J4: =COLUMN()-COLUMN($E$4) -> 5 | K4: =COLUMN()-COLUMN($E$4) -> 6 | L4: =COLUMN()-COLUMN($E$4) -> 7 | M4: =COLUMN()-COLUMN($E$4) -> 8 | ... W4: =COLUMN()-COLUMN($E$4) -> 18
A5: Показатель | B5: Ед. | C5: Параметр | D5: Итого | E5: Старт | F5: =EDATE(Дата_начала,F$4-1) -> 46327 | G5: =EDATE(Дата_начала,G$4-1) -> 46357 | H5: =EDATE(Дата_начала,H$4-1) -> 46388 | I5: =EDATE(Дата_начала,I$4-1) -> 46419 | J5: =EDATE(Дата_начала,J$4-1) -> 46447 | K5: =EDATE(Дата_начала,K$4-1) -> 46478 | L5: =EDATE(Дата_начала,L$4-1) -> 46508 | M5: =EDATE(Дата_начала,M$4-1) -> 46539 | ... W5: =EDATE(Дата_начала,W$4-1) -> 46844
A7: 1. Спрос: план выкупов | C7: плато, шт/мес
A8: =""&Допущения!$C$38 -> Органайзер в багажник | B8: шт | C8: =Допущения!$C$44 -> 140 | D8: =SUM(F8:W8) -> 2100 | F8: =ROUND($C8*INDEX(Темп_продаж,F$4)*Множитель_продаж,0) -> 0 | G8: =ROUND($C8*INDEX(Темп_продаж,G$4)*Множитель_продаж,0) -> 0 | H8: =ROUND($C8*INDEX(Темп_продаж,H$4)*Множитель_продаж,0) -> 42 | I8: =ROUND($C8*INDEX(Темп_продаж,I$4)*Множитель_продаж,0) -> 70 | J8: =ROUND($C8*INDEX(Темп_продаж,J$4)*Множитель_продаж,0) -> 98 | K8: =ROUND($C8*INDEX(Темп_продаж,K$4)*Множитель_продаж,0) -> 119 | L8: =ROUND($C8*INDEX(Темп_продаж,L$4)*Множитель_продаж,0) -> 140 | M8: =ROUND($C8*INDEX(Темп_продаж,M$4)*Множитель_продаж,0) -> 140 | ... W8: =ROUND($C8*INDEX(Темп_продаж,W$4)*Множитель_продаж,0) -> 147
A9: =""&Допущения!$D$38 -> Автопылесос беспроводной | B9: шт | C9: =Допущения!$D$44 -> 120 | D9: =SUM(F9:W9) -> 1800 | F9: =ROUND($C9*INDEX(Темп_продаж,F$4)*Множитель_продаж,0) -> 0 | G9: =ROUND($C9*INDEX(Темп_продаж,G$4)*Множитель_продаж,0) -> 0 | H9: =ROUND($C9*INDEX(Темп_продаж,H$4)*Множитель_продаж,0) -> 36 | I9: =ROUND($C9*INDEX(Темп_продаж,I$4)*Множитель_продаж,0) -> 60 | J9: =ROUND($C9*INDEX(Темп_продаж,J$4)*Множитель_продаж,0) -> 84 | K9: =ROUND($C9*INDEX(Темп_продаж,K$4)*Множитель_продаж,0) -> 102 | L9: =ROUND($C9*INDEX(Темп_продаж,L$4)*Множитель_продаж,0) -> 120 | M9: =ROUND($C9*INDEX(Темп_продаж,M$4)*Множитель_продаж,0) -> 120 | ... W9: =ROUND($C9*INDEX(Темп_продаж,W$4)*Множитель_продаж,0) -> 126
A10: =""&Допущения!$E$38 -> Держатель телефона MagSafe | B10: шт | C10: =Допущения!$E$44 -> 260 | D10: =SUM(F10:W10) -> 3900 | F10: =ROUND($C10*INDEX(Темп_продаж,F$4)*Множитель_продаж,0) -> 0 | G10: =ROUND($C10*INDEX(Темп_продаж,G$4)*Множитель_продаж,0) -> 0 | H10: =ROUND($C10*INDEX(Темп_продаж,H$4)*Множитель_продаж,0) -> 78 | I10: =ROUND($C10*INDEX(Темп_продаж,I$4)*Множитель_продаж,0) -> 130 | J10: =ROUND($C10*INDEX(Темп_продаж,J$4)*Множитель_продаж,0) -> 182 | K10: =ROUND($C10*INDEX(Темп_продаж,K$4)*Множитель_продаж,0) -> 221 | L10: =ROUND($C10*INDEX(Темп_продаж,L$4)*Множитель_продаж,0) -> 260 | M10: =ROUND($C10*INDEX(Темп_продаж,M$4)*Множитель_продаж,0) -> 260 | ... W10: =ROUND($C10*INDEX(Темп_продаж,W$4)*Множитель_продаж,0) -> 273
A11: =""&Допущения!$F$38 -> Чехлы на сиденья, комплект | B11: шт | C11: =Допущения!$F$44 -> 60 | D11: =SUM(F11:W11) -> 900 | F11: =ROUND($C11*INDEX(Темп_продаж,F$4)*Множитель_продаж,0) -> 0 | G11: =ROUND($C11*INDEX(Темп_продаж,G$4)*Множитель_продаж,0) -> 0 | H11: =ROUND($C11*INDEX(Темп_продаж,H$4)*Множитель_продаж,0) -> 18 | I11: =ROUND($C11*INDEX(Темп_продаж,I$4)*Множитель_продаж,0) -> 30 | J11: =ROUND($C11*INDEX(Темп_продаж,J$4)*Множитель_продаж,0) -> 42 | K11: =ROUND($C11*INDEX(Темп_продаж,K$4)*Множитель_продаж,0) -> 51 | L11: =ROUND($C11*INDEX(Темп_продаж,L$4)*Множитель_продаж,0) -> 60 | M11: =ROUND($C11*INDEX(Темп_продаж,M$4)*Множитель_продаж,0) -> 60 | ... W11: =ROUND($C11*INDEX(Темп_продаж,W$4)*Множитель_продаж,0) -> 63
A12: =""&Допущения!$G$38 -> Видеорегистратор Wi-Fi | B12: шт | C12: =Допущения!$G$44 -> 90 | D12: =SUM(F12:W12) -> 1353 | F12: =ROUND($C12*INDEX(Темп_продаж,F$4)*Множитель_продаж,0) -> 0 | G12: =ROUND($C12*INDEX(Темп_продаж,G$4)*Множитель_продаж,0) -> 0 | H12: =ROUND($C12*INDEX(Темп_продаж,H$4)*Множитель_продаж,0) -> 27 | I12: =ROUND($C12*INDEX(Темп_продаж,I$4)*Множитель_продаж,0) -> 45 | J12: =ROUND($C12*INDEX(Темп_продаж,J$4)*Множитель_продаж,0) -> 63 | K12: =ROUND($C12*INDEX(Темп_продаж,K$4)*Множитель_продаж,0) -> 77 | L12: =ROUND($C12*INDEX(Темп_продаж,L$4)*Множитель_продаж,0) -> 90 | M12: =ROUND($C12*INDEX(Темп_продаж,M$4)*Множитель_продаж,0) -> 90 | ... W12: =ROUND($C12*INDEX(Темп_продаж,W$4)*Множитель_продаж,0) -> 95
A13: Итого | B13: шт | D13: =SUM(F13:W13) -> 10053 | F13: =SUM(F8:F12) -> 0 | G13: =SUM(G8:G12) -> 0 | H13: =SUM(H8:H12) -> 201 | I13: =SUM(I8:I12) -> 335 | J13: =SUM(J8:J12) -> 469 | K13: =SUM(K8:K12) -> 570 | L13: =SUM(L8:L12) -> 670 | M13: =SUM(M8:M12) -> 670 | ... W13: =SUM(W8:W12) -> 704
A15: 2. Поступление на склад маркетплейса
A16: =""&Допущения!$C$38 -> Органайзер в багажник | B16: шт | D16: =SUM(F16:W16) -> 2400 | F16: =SUMIFS($E$71:E$71,$E$4:E$4,F$4-Срок_поставки) -> 0 | G16: =SUMIFS($E$71:F$71,$E$4:F$4,G$4-Срок_поставки) -> 0 | H16: =SUMIFS($E$71:G$71,$E$4:G$4,H$4-Срок_поставки) -> 200 | I16: =SUMIFS($E$71:H$71,$E$4:H$4,I$4-Срок_поставки) -> 200 | J16: =SUMIFS($E$71:I$71,$E$4:I$4,J$4-Срок_поставки) -> 0 | K16: =SUMIFS($E$71:J$71,$E$4:J$4,K$4-Срок_поставки) -> 200 | L16: =SUMIFS($E$71:K$71,$E$4:K$4,L$4-Срок_поставки) -> 200 | M16: =SUMIFS($E$71:L$71,$E$4:L$4,M$4-Срок_поставки) -> 0 | ... W16: =SUMIFS($E$71:V$71,$E$4:V$4,W$4-Срок_поставки) -> 200
A17: =""&Допущения!$D$38 -> Автопылесос беспроводной | B17: шт | D17: =SUM(F17:W17) -> 1950 | F17: =SUMIFS($E$72:E$72,$E$4:E$4,F$4-Срок_поставки) -> 0 | G17: =SUMIFS($E$72:F$72,$E$4:F$4,G$4-Срок_поставки) -> 0 | H17: =SUMIFS($E$72:G$72,$E$4:G$4,H$4-Срок_поставки) -> 150 | I17: =SUMIFS($E$72:H$72,$E$4:H$4,I$4-Срок_поставки) -> 150 | J17: =SUMIFS($E$72:I$72,$E$4:I$4,J$4-Срок_поставки) -> 0 | K17: =SUMIFS($E$72:J$72,$E$4:J$4,K$4-Срок_поставки) -> 150 | L17: =SUMIFS($E$72:K$72,$E$4:K$4,L$4-Срок_поставки) -> 150 | M17: =SUMIFS($E$72:L$72,$E$4:L$4,M$4-Срок_поставки) -> 150 | ... W17: =SUMIFS($E$72:V$72,$E$4:V$4,W$4-Срок_поставки) -> 150
A18: =""&Допущения!$E$38 -> Держатель телефона MagSafe | B18: шт | D18: =SUM(F18:W18) -> 4200 | F18: =SUMIFS($E$73:E$73,$E$4:E$4,F$4-Срок_поставки) -> 0 | G18: =SUMIFS($E$73:F$73,$E$4:F$4,G$4-Срок_поставки) -> 0 | H18: =SUMIFS($E$73:G$73,$E$4:G$4,H$4-Срок_поставки) -> 300 | I18: =SUMIFS($E$73:H$73,$E$4:H$4,I$4-Срок_поставки) -> 300 | J18: =SUMIFS($E$73:I$73,$E$4:I$4,J$4-Срок_поставки) -> 300 | K18: =SUMIFS($E$73:J$73,$E$4:J$4,K$4-Срок_поставки) -> 0 | L18: =SUMIFS($E$73:K$73,$E$4:K$4,L$4-Срок_поставки) -> 300 | M18: =SUMIFS($E$73:L$73,$E$4:L$4,M$4-Срок_поставки) -> 300 | ... W18: =SUMIFS($E$73:V$73,$E$4:V$4,W$4-Срок_поставки) -> 300
A19: =""&Допущения!$F$38 -> Чехлы на сиденья, комплект | B19: шт | D19: =SUM(F19:W19) -> 1000 | F19: =SUMIFS($E$74:E$74,$E$4:E$4,F$4-Срок_поставки) -> 0 | G19: =SUMIFS($E$74:F$74,$E$4:F$4,G$4-Срок_поставки) -> 0 | H19: =SUMIFS($E$74:G$74,$E$4:G$4,H$4-Срок_поставки) -> 100 | I19: =SUMIFS($E$74:H$74,$E$4:H$4,I$4-Срок_поставки) -> 0 | J19: =SUMIFS($E$74:I$74,$E$4:I$4,J$4-Срок_поставки) -> 100 | K19: =SUMIFS($E$74:J$74,$E$4:J$4,K$4-Срок_поставки) -> 100 | L19: =SUMIFS($E$74:K$74,$E$4:K$4,L$4-Срок_поставки) -> 0 | M19: =SUMIFS($E$74:L$74,$E$4:L$4,M$4-Срок_поставки) -> 100 | ... W19: =SUMIFS($E$74:V$74,$E$4:V$4,W$4-Срок_поставки) -> 100
A20: =""&Допущения!$G$38 -> Видеорегистратор Wi-Fi | B20: шт | D20: =SUM(F20:W20) -> 1500 | F20: =SUMIFS($E$75:E$75,$E$4:E$4,F$4-Срок_поставки) -> 0 | G20: =SUMIFS($E$75:F$75,$E$4:F$4,G$4-Срок_поставки) -> 0 | H20: =SUMIFS($E$75:G$75,$E$4:G$4,H$4-Срок_поставки) -> 100 | I20: =SUMIFS($E$75:H$75,$E$4:H$4,I$4-Срок_поставки) -> 100 | J20: =SUMIFS($E$75:I$75,$E$4:I$4,J$4-Срок_поставки) -> 100 | K20: =SUMIFS($E$75:J$75,$E$4:J$4,K$4-Срок_поставки) -> 100 | L20: =SUMIFS($E$75:K$75,$E$4:K$4,L$4-Срок_поставки) -> 0 | M20: =SUMIFS($E$75:L$75,$E$4:L$4,M$4-Срок_поставки) -> 100 | ... W20: =SUMIFS($E$75:V$75,$E$4:V$4,W$4-Срок_поставки) -> 100
A21: Итого | B21: шт | D21: =SUM(F21:W21) -> 11050 | F21: =SUM(F16:F20) -> 0 | G21: =SUM(G16:G20) -> 0 | H21: =SUM(H16:H20) -> 850 | I21: =SUM(I16:I20) -> 750 | J21: =SUM(J16:J20) -> 500 | K21: =SUM(K16:K20) -> 550 | L21: =SUM(L16:L20) -> 650 | M21: =SUM(M16:M20) -> 650 | ... W21: =SUM(W16:W20) -> 850
A23: 3. Продажи (выкупы) = min(спрос, доступный товар)
A24: =""&Допущения!$C$38 -> Органайзер в багажник | B24: шт | D24: =SUM(F24:W24) -> 2100 | F24: =MIN(F8,E40+F16) -> 0 | G24: =MIN(G8,F40+G16) -> 0 | H24: =MIN(H8,G40+H16) -> 42 | I24: =MIN(I8,H40+I16) -> 70 | J24: =MIN(J8,I40+J16) -> 98 | K24: =MIN(K8,J40+K16) -> 119 | L24: =MIN(L8,K40+L16) -> 140 | M24: =MIN(M8,L40+M16) -> 140 | ... W24: =MIN(W8,V40+W16) -> 147
A25: =""&Допущения!$D$38 -> Автопылесос беспроводной | B25: шт | D25: =SUM(F25:W25) -> 1800 | F25: =MIN(F9,E41+F17) -> 0 | G25: =MIN(G9,F41+G17) -> 0 | H25: =MIN(H9,G41+H17) -> 36 | I25: =MIN(I9,H41+I17) -> 60 | J25: =MIN(J9,I41+J17) -> 84 | K25: =MIN(K9,J41+K17) -> 102 | L25: =MIN(L9,K41+L17) -> 120 | M25: =MIN(M9,L41+M17) -> 120 | ... W25: =MIN(W9,V41+W17) -> 126
A26: =""&Допущения!$E$38 -> Держатель телефона MagSafe | B26: шт | D26: =SUM(F26:W26) -> 3900 | F26: =MIN(F10,E42+F18) -> 0 | G26: =MIN(G10,F42+G18) -> 0 | H26: =MIN(H10,G42+H18) -> 78 | I26: =MIN(I10,H42+I18) -> 130 | J26: =MIN(J10,I42+J18) -> 182 | K26: =MIN(K10,J42+K18) -> 221 | L26: =MIN(L10,K42+L18) -> 260 | M26: =MIN(M10,L42+M18) -> 260 | ... W26: =MIN(W10,V42+W18) -> 273
A27: =""&Допущения!$F$38 -> Чехлы на сиденья, комплект | B27: шт | D27: =SUM(F27:W27) -> 900 | F27: =MIN(F11,E43+F19) -> 0 | G27: =MIN(G11,F43+G19) -> 0 | H27: =MIN(H11,G43+H19) -> 18 | I27: =MIN(I11,H43+I19) -> 30 | J27: =MIN(J11,I43+J19) -> 42 | K27: =MIN(K11,J43+K19) -> 51 | L27: =MIN(L11,K43+L19) -> 60 | M27: =MIN(M11,L43+M19) -> 60 | ... W27: =MIN(W11,V43+W19) -> 63
A28: =""&Допущения!$G$38 -> Видеорегистратор Wi-Fi | B28: шт | D28: =SUM(F28:W28) -> 1353 | F28: =MIN(F12,E44+F20) -> 0 | G28: =MIN(G12,F44+G20) -> 0 | H28: =MIN(H12,G44+H20) -> 27 | I28: =MIN(I12,H44+I20) -> 45 | J28: =MIN(J12,I44+J20) -> 63 | K28: =MIN(K12,J44+K20) -> 77 | L28: =MIN(L12,K44+L20) -> 90 | M28: =MIN(M12,L44+M20) -> 90 | ... W28: =MIN(W12,V44+W20) -> 95
A29: Итого | B29: шт | D29: =SUM(F29:W29) -> 10053 | F29: =SUM(F24:F28) -> 0 | G29: =SUM(G24:G28) -> 0 | H29: =SUM(H24:H28) -> 201 | I29: =SUM(I24:I28) -> 335 | J29: =SUM(J24:J28) -> 469 | K29: =SUM(K24:K28) -> 570 | L29: =SUM(L24:L28) -> 670 | M29: =SUM(M24:M28) -> 670 | ... W29: =SUM(W24:W28) -> 704
A31: 4. Упущенные продажи — товара не было
A32: =""&Допущения!$C$38 -> Органайзер в багажник | B32: шт | D32: =SUM(F32:W32) -> 0 | F32: =F8-F24 -> 0 | G32: =G8-G24 -> 0 | H32: =H8-H24 -> 0 | I32: =I8-I24 -> 0 | J32: =J8-J24 -> 0 | K32: =K8-K24 -> 0 | L32: =L8-L24 -> 0 | M32: =M8-M24 -> 0 | ... W32: =W8-W24 -> 0
A33: =""&Допущения!$D$38 -> Автопылесос беспроводной | B33: шт | D33: =SUM(F33:W33) -> 0 | F33: =F9-F25 -> 0 | G33: =G9-G25 -> 0 | H33: =H9-H25 -> 0 | I33: =I9-I25 -> 0 | J33: =J9-J25 -> 0 | K33: =K9-K25 -> 0 | L33: =L9-L25 -> 0 | M33: =M9-M25 -> 0 | ... W33: =W9-W25 -> 0
A34: =""&Допущения!$E$38 -> Держатель телефона MagSafe | B34: шт | D34: =SUM(F34:W34) -> 0 | F34: =F10-F26 -> 0 | G34: =G10-G26 -> 0 | H34: =H10-H26 -> 0 | I34: =I10-I26 -> 0 | J34: =J10-J26 -> 0 | K34: =K10-K26 -> 0 | L34: =L10-L26 -> 0 | M34: =M10-M26 -> 0 | ... W34: =W10-W26 -> 0
A35: =""&Допущения!$F$38 -> Чехлы на сиденья, комплект | B35: шт | D35: =SUM(F35:W35) -> 0 | F35: =F11-F27 -> 0 | G35: =G11-G27 -> 0 | H35: =H11-H27 -> 0 | I35: =I11-I27 -> 0 | J35: =J11-J27 -> 0 | K35: =K11-K27 -> 0 | L35: =L11-L27 -> 0 | M35: =M11-M27 -> 0 | ... W35: =W11-W27 -> 0
A36: =""&Допущения!$G$38 -> Видеорегистратор Wi-Fi | B36: шт | D36: =SUM(F36:W36) -> 0 | F36: =F12-F28 -> 0 | G36: =G12-G28 -> 0 | H36: =H12-H28 -> 0 | I36: =I12-I28 -> 0 | J36: =J12-J28 -> 0 | K36: =K12-K28 -> 0 | L36: =L12-L28 -> 0 | M36: =M12-M28 -> 0 | ... W36: =W12-W28 -> 0
A37: Итого | B37: шт | D37: =SUM(F37:W37) -> 0 | F37: =SUM(F32:F36) -> 0 | G37: =SUM(G32:G36) -> 0 | H37: =SUM(H32:H36) -> 0 | I37: =SUM(I32:I36) -> 0 | J37: =SUM(J32:J36) -> 0 | K37: =SUM(K32:K36) -> 0 | L37: =SUM(L32:L36) -> 0 | M37: =SUM(M32:M36) -> 0 | ... W37: =SUM(W32:W36) -> 0
A39: 5. Остаток на складе на конец месяца | C39: себест. 1 шт, ₽
A40: =""&Допущения!$C$38 -> Органайзер в багажник | B40: шт | C40: ='Юнит-экономика'!$C$20 -> 1026.7768 | E40: =Допущения!$C$45 -> 0 | F40: =E40+F16-F24 -> 0 | G40: =F40+G16-G24 -> 0 | H40: =G40+H16-H24 -> 158 | I40: =H40+I16-I24 -> 288 | J40: =I40+J16-J24 -> 190 | K40: =J40+K16-K24 -> 271 | L40: =K40+L16-L24 -> 331 | M40: =L40+M16-M24 -> 191 | ... W40: =V40+W16-W24 -> 300
A41: =""&Допущения!$D$38 -> Автопылесос беспроводной | B41: шт | C41: ='Юнит-экономика'!$D$20 -> 1313.3625 | E41: =Допущения!$D$45 -> 0 | F41: =E41+F17-F25 -> 0 | G41: =F41+G17-G25 -> 0 | H41: =G41+H17-H25 -> 114 | I41: =H41+I17-I25 -> 204 | J41: =I41+J17-J25 -> 120 | K41: =J41+K17-K25 -> 168 | L41: =K41+L17-L25 -> 198 | M41: =L41+M17-M25 -> 228 | ... W41: =V41+W17-W25 -> 150
A42: =""&Допущения!$E$38 -> Держатель телефона MagSafe | B42: шт | C42: ='Юнит-экономика'!$E$20 -> 473.76547 | E42: =Допущения!$E$45 -> 0 | F42: =E42+F18-F26 -> 0 | G42: =F42+G18-G26 -> 0 | H42: =G42+H18-H26 -> 222 | I42: =H42+I18-I26 -> 392 | J42: =I42+J18-J26 -> 510 | K42: =J42+K18-K26 -> 289 | L42: =K42+L18-L26 -> 329 | M42: =L42+M18-M26 -> 369 | ... W42: =V42+W18-W26 -> 300
A43: =""&Допущения!$F$38 -> Чехлы на сиденья, комплект | B43: шт | C43: ='Юнит-экономика'!$F$20 -> 2705.811 | E43: =Допущения!$F$45 -> 0 | F43: =E43+F19-F27 -> 0 | G43: =F43+G19-G27 -> 0 | H43: =G43+H19-H27 -> 82 | I43: =H43+I19-I27 -> 52 | J43: =I43+J19-J27 -> 110 | K43: =J43+K19-K27 -> 159 | L43: =K43+L19-L27 -> 99 | M43: =L43+M19-M27 -> 139 | ... W43: =V43+W19-W27 -> 100
A44: =""&Допущения!$G$38 -> Видеорегистратор Wi-Fi | B44: шт | C44: ='Юнит-экономика'!$G$20 -> 1710.5292 | E44: =Допущения!$G$45 -> 0 | F44: =E44+F20-F28 -> 0 | G44: =F44+G20-G28 -> 0 | H44: =G44+H20-H28 -> 73 | I44: =H44+I20-I28 -> 128 | J44: =I44+J20-J28 -> 165 | K44: =J44+K20-K28 -> 188 | L44: =K44+L20-L28 -> 98 | M44: =L44+M20-M28 -> 108 | ... W44: =V44+W20-W28 -> 147
A45: Итого | B45: шт | E45: =SUM(E40:E44) -> 0 | F45: =SUM(F40:F44) -> 0 | G45: =SUM(G40:G44) -> 0 | H45: =SUM(H40:H44) -> 649 | I45: =SUM(I40:I44) -> 1064 | J45: =SUM(J40:J44) -> 1095 | K45: =SUM(K40:K44) -> 1075 | L45: =SUM(L40:L44) -> 1055 | ... W45: =SUM(W40:W44) -> 997
...

Sheet Денежный поток
A1: Денежный поток по месяцам
A2: Покупка товара — деньги уходят при заказе (товар) и при поступлении (доставка, таможня). Выручка приходит с задержкой выплат маркетплейса. Красным — месяцы, когда денег не хватает (кассовый разрыв).
A3: ДЕМО-ДАННЫЕ: все цифры — пример. Ставки пошлин, НДС, налогов и тарифы маркетплейса уточните под свой товар.
A4: Месяц № | F4: =COLUMN()-COLUMN($E$4) -> 1 | G4: =COLUMN()-COLUMN($E$4) -> 2 | H4: =COLUMN()-COLUMN($E$4) -> 3 | I4: =COLUMN()-COLUMN($E$4) -> 4 | J4: =COLUMN()-COLUMN($E$4) -> 5 | K4: =COLUMN()-COLUMN($E$4) -> 6 | L4: =COLUMN()-COLUMN($E$4) -> 7 | M4: =COLUMN()-COLUMN($E$4) -> 8 | ... W4: =COLUMN()-COLUMN($E$4) -> 18
A5: Показатель | B5: Ед. | C5: Параметр | D5: Итого | E5: Старт | F5: =EDATE(Дата_начала,F$4-1) -> 46327 | G5: =EDATE(Дата_начала,G$4-1) -> 46357 | H5: =EDATE(Дата_начала,H$4-1) -> 46388 | I5: =EDATE(Дата_начала,I$4-1) -> 46419 | J5: =EDATE(Дата_начала,J$4-1) -> 46447 | K5: =EDATE(Дата_начала,K$4-1) -> 46478 | L5: =EDATE(Дата_начала,L$4-1) -> 46508 | M5: =EDATE(Дата_начала,M$4-1) -> 46539 | ... W5: =EDATE(Дата_начала,W$4-1) -> 46844
A7: Остаток денег на начало месяца | B7: ₽ | F7: =E65 -> 2000000 | G7: =F65 -> 1188093.2 | H7: =G65 -> 742913.1 | I7: =H65 -> 56803.691 | J7: =I65 -> -315376.47 | K7: =J65 -> -218123.59 | L7: =K65 -> -397876.69 | M7: =L65 -> -84529.663 | ... W7: =V65 -> 2549951
A9: ПОСТУПЛЕНИЯ
A10: Задержка выплат: целых месяцев (служебная) | C10: =INT(Задержка_выплат_дн/Дней_в_месяце) -> 0
A11: Доля выплат, которая приходит ещё на месяц позже (служебная) | C11: =Задержка_выплат_дн/Дней_в_месяце-$C$10 -> 0.46666667
A12: Начислено маркетплейсом к выплате (выручка − комиссия − логистика) | B12: ₽ | D12: =SUM(F12:W12) -> 18721816 | F12: =ОПиУ!F8-ОПиУ!F23-ОПиУ!F29 -> 0 | G12: =ОПиУ!G8-ОПиУ!G23-ОПиУ!G29 -> 0 | H12: =ОПиУ!H8-ОПиУ!H23-ОПиУ!H29 -> 374268.1 | I12: =ОПиУ!I8-ОПиУ!I23-ОПиУ!I29 -> 623780.16 | J12: =ОПиУ!J8-ОПиУ!J23-ОПиУ!J29 -> 873292.22 | K12: =ОПиУ!K8-ОПиУ!K23-ОПиУ!K29 -> 1061828.2 | L12: =ОПиУ!L8-ОПиУ!L23-ОПиУ!L29 -> 1247560.3 | M12: =ОПиУ!M8-ОПиУ!M23-ОПиУ!M29 -> 1247560.3 | ... W12: =ОПиУ!W8-ОПиУ!W23-ОПиУ!W29 -> 1311340.3
A13: Выплаты маркетплейса | B13: ₽ | D13: =SUM(F13:W13) -> 18109858 | F13: =(1-$C$11)*SUMIFS($F$12:$W$12,$F$4:$W$4,F$4-$C$10)+$C$11*SUMIFS($F$12:$W$12,$F$4:$W$4,F$4-$C$10-1) -> 0 | G13: =(1-$C$11)*SUMIFS($F$12:$W$12,$F$4:$W$4,G$4-$C$10)+$C$11*SUMIFS($F$12:$W$12,$F$4:$W$4,G$4-$C$10-1) -> 0 | H13: =(1-$C$11)*SUMIFS($F$12:$W$12,$F$4:$W$4,H$4-$C$10)+$C$11*SUMIFS($F$12:$W$12,$F$4:$W$4,H$4-$C$10-1) -> 199609.65 | I13: =(1-$C$11)*SUMIFS($F$12:$W$12,$F$4:$W$4,I$4-$C$10)+$C$11*SUMIFS($F$12:$W$12,$F$4:$W$4,I$4-$C$10-1) -> 507341.2 | J13: =(1-$C$11)*SUMIFS($F$12:$W$12,$F$4:$W$4,J$4-$C$10)+$C$11*SUMIFS($F$12:$W$12,$F$4:$W$4,J$4-$C$10-1) -> 756853.26 | K13: =(1-$C$11)*SUMIFS($F$12:$W$12,$F$4:$W$4,K$4-$C$10)+$C$11*SUMIFS($F$12:$W$12,$F$4:$W$4,K$4-$C$10-1) -> 973844.74 | L13: =(1-$C$11)*SUMIFS($F$12:$W$12,$F$4:$W$4,L$4-$C$10)+$C$11*SUMIFS($F$12:$W$12,$F$4:$W$4,L$4-$C$10-1) -> 1160885.3 | M13: =(1-$C$11)*SUMIFS($F$12:$W$12,$F$4:$W$4,M$4-$C$10)+$C$11*SUMIFS($F$12:$W$12,$F$4:$W$4,M$4-$C$10-1) -> 1247560.3 | ... W13: =(1-$C$11)*SUMIFS($F$12:$W$12,$F$4:$W$4,W$4-$C$10)+$C$11*SUMIFS($F$12:$W$12,$F$4:$W$4,W$4-$C$10-1) -> 1311340.3
A15: ВЫПЛАТЫ
A16: Оплата поставщику (товар + агент + банк) | B16: ₽ | D16: =SUM(F16:W16) -> 7544803.6 | F16: =SUM(F17:F21) -> 526906.8 | G16: =SUM(G17:G21) -> 395180.1 | H16: =SUM(H17:H21) -> 337471.26 | I16: =SUM(I17:I21) -> 444107.16 | J16: =SUM(J17:J21) -> 272235.18 | K16: =SUM(K17:K21) -> 446616.24 | L16: =SUM(L17:L21) -> 395180.1 | M16: =SUM(M17:M21) -> 417761.82 | ... W16: =SUM(W17:W21) -> 395180.1
A17: =""&Допущения!$C$38 -> Органайзер в багажник | B17: ₽ | C17: ='Юнит-экономика'!$C$21 -> 401.4528 | D17: =SUM(F17:W17) -> 1043777.3 | F17: ='Закупки и склад'!F$71*$C17 -> 80290.56 | G17: ='Закупки и склад'!G$71*$C17 -> 80290.56 | H17: ='Закупки и склад'!H$71*$C17 -> 0 | I17: ='Закупки и склад'!I$71*$C17 -> 80290.56 | J17: ='Закупки и склад'!J$71*$C17 -> 80290.56 | K17: ='Закупки и склад'!K$71*$C17 -> 0 | L17: ='Закупки и склад'!L$71*$C17 -> 80290.56 | M17: ='Закупки и склад'!M$71*$C17 -> 80290.56 | ... W17: ='Закупки и склад'!W$71*$C17 -> 80290.56
A18: =""&Допущения!$D$38 -> Автопылесос беспроводной | B18: ₽ | C18: ='Юнит-экономика'!$D$21 -> 727.6332 | D18: =SUM(F18:W18) -> 1637174.7 | F18: ='Закупки и склад'!F$72*$C18 -> 109144.98 | G18: ='Закупки и склад'!G$72*$C18 -> 109144.98 | H18: ='Закупки и склад'!H$72*$C18 -> 0 | I18: ='Закупки и склад'!I$72*$C18 -> 109144.98 | J18: ='Закупки и склад'!J$72*$C18 -> 109144.98 | K18: ='Закупки и склад'!K$72*$C18 -> 109144.98 | L18: ='Закупки и склад'!L$72*$C18 -> 109144.98 | M18: ='Закупки и склад'!M$72*$C18 -> 0 | ... W18: ='Закупки и склад'!W$72*$C18 -> 109144.98
A19: =""&Допущения!$E$38 -> Держатель телефона MagSafe | B19: ₽ | C19: ='Юнит-экономика'!$E$21 -> 275.9988 | D19: =SUM(F19:W19) -> 1324794.2 | F19: ='Закупки и склад'!F$73*$C19 -> 82799.64 | G19: ='Закупки и склад'!G$73*$C19 -> 82799.64 | H19: ='Закупки и склад'!H$73*$C19 -> 82799.64 | I19: ='Закупки и склад'!I$73*$C19 -> 0 | J19: ='Закупки и склад'!J$73*$C19 -> 82799.64 | K19: ='Закупки и склад'!K$73*$C19 -> 82799.64 | L19: ='Закупки и склад'!L$73*$C19 -> 82799.64 | M19: ='Закупки и склад'!M$73*$C19 -> 82799.64 | ... W19: ='Закупки и склад'!W$73*$C19 -> 82799.64
A20: =""&Допущения!$F$38 -> Чехлы на сиденья, комплект | B20: ₽ | C20: ='Юнит-экономика'!$F$21 -> 1317.267 | D20: =SUM(F20:W20) -> 1448993.7 | F20: ='Закупки и склад'!F$74*$C20 -> 131726.7 | G20: ='Закупки и склад'!G$74*$C20 -> 0 | H20: ='Закупки и склад'!H$74*$C20 -> 131726.7 | I20: ='Закупки и склад'!I$74*$C20 -> 131726.7 | J20: ='Закупки и склад'!J$74*$C20 -> 0 | K20: ='Закупки и склад'!K$74*$C20 -> 131726.7 | L20: ='Закупки и склад'!L$74*$C20 -> 0 | M20: ='Закупки и склад'!M$74*$C20 -> 131726.7 | ... W20: ='Закупки и склад'!W$74*$C20 -> 0
A21: =""&Допущения!$G$38 -> Видеорегистратор Wi-Fi | B21: ₽ | C21: ='Юнит-экономика'!$G$21 -> 1229.4492 | D21: =SUM(F21:W21) -> 2090063.6 | F21: ='Закупки и склад'!F$75*$C21 -> 122944.92 | G21: ='Закупки и склад'!G$75*$C21 -> 122944.92 | H21: ='Закупки и склад'!H$75*$C21 -> 122944.92 | I21: ='Закупки и склад'!I$75*$C21 -> 122944.92 | J21: ='Закупки и склад'!J$75*$C21 -> 0 | K21: ='Закупки и склад'!K$75*$C21 -> 122944.92 | L21: ='Закупки и склад'!L$75*$C21 -> 122944.92 | M21: ='Закупки и склад'!M$75*$C21 -> 122944.92 | ... W21: ='Закупки и склад'!W$75*$C21 -> 122944.92
A22: Доставка из Китая | B22: ₽ | D22: =SUM(F22:W22) -> 2101400 | F22: =SUM(F23:F27) -> 0 | G22: =SUM(G23:G27) -> 0 | H22: =SUM(H23:H27) -> 176400 | I22: =SUM(I23:I27) -> 119200 | J22: =SUM(J23:J27) -> 85800 | K22: =SUM(K23:K27) -> 156600 | L22: =SUM(L23:L27) -> 110400 | M22: =SUM(M23:M27) -> 118800 | ... W22: =SUM(W23:W27) -> 176400
A23: =""&Допущения!$C$38 -> Органайзер в багажник | B23: ₽ | C23: ='Юнит-экономика'!$C$13 -> 288 | D23: =SUM(F23:W23) -> 691200 | F23: ='Закупки и склад'!F$16*$C23 -> 0 | G23: ='Закупки и склад'!G$16*$C23 -> 0 | H23: ='Закупки и склад'!H$16*$C23 -> 57600 | I23: ='Закупки и склад'!I$16*$C23 -> 57600 | J23: ='Закупки и склад'!J$16*$C23 -> 0 | K23: ='Закупки и склад'!K$16*$C23 -> 57600 | L23: ='Закупки и склад'!L$16*$C23 -> 57600 | M23: ='Закупки и склад'!M$16*$C23 -> 0 | ... W23: ='Закупки и склад'!W$16*$C23 -> 57600
A24: =""&Допущения!$D$38 -> Автопылесос беспроводной | B24: ₽ | C24: ='Юнит-экономика'!$D$13 -> 220 | D24: =SUM(F24:W24) -> 429000 | F24: ='Закупки и склад'!F$17*$C24 -> 0 | G24: ='Закупки и склад'!G$17*$C24 -> 0 | H24: ='Закупки и склад'!H$17*$C24 -> 33000 | I24: ='Закупки и склад'!I$17*$C24 -> 33000 | J24: ='Закупки и склад'!J$17*$C24 -> 0 | K24: ='Закупки и склад'!K$17*$C24 -> 33000 | L24: ='Закупки и склад'!L$17*$C24 -> 33000 | M24: ='Закупки и склад'!M$17*$C24 -> 33000 | ... W24: ='Закупки и склад'!W$17*$C24 -> 33000
A25: =""&Допущения!$E$38 -> Держатель телефона MagSafe | B25: ₽ | C25: ='Юнит-экономика'!$E$13 -> 66 | D25: =SUM(F25:W25) -> 277200 | F25: ='Закупки и склад'!F$18*$C25 -> 0 | G25: ='Закупки и склад'!G$18*$C25 -> 0 | H25: ='Закупки и склад'!H$18*$C25 -> 19800 | I25: ='Закупки и склад'!I$18*$C25 -> 19800 | J25: ='Закупки и склад'!J$18*$C25 -> 19800 | K25: ='Закупки и склад'!K$18*$C25 -> 0 | L25: ='Закупки и склад'!L$18*$C25 -> 19800 | M25: ='Закупки и склад'!M$18*$C25 -> 19800 | ... W25: ='Закупки и склад'!W$18*$C25 -> 19800
A26: =""&Допущения!$F$38 -> Чехлы на сиденья, комплект | B26: ₽ | C26: ='Юнит-экономика'!$F$13 -> 572 | D26: =SUM(F26:W26) -> 572000 | F26: ='Закупки и склад'!F$19*$C26 -> 0 | G26: ='Закупки и склад'!G$19*$C26 -> 0 | H26: ='Закупки и склад'!H$19*$C26 -> 57200 | I26: ='Закупки и склад'!I$19*$C26 -> 0 | J26: ='Закупки и склад'!J$19*$C26 -> 57200 | K26: ='Закупки и склад'!K$19*$C26 -> 57200 | L26: ='Закупки и склад'!L$19*$C26 -> 0 | M26: ='Закупки и склад'!M$19*$C26 -> 57200 | ... W26: ='Закупки и склад'!W$19*$C26 -> 57200
A27: =""&Допущения!$G$38 -> Видеорегистратор Wi-Fi | B27: ₽ | C27: ='Юнит-экономика'!$G$13 -> 88 | D27: =SUM(F27:W27) -> 132000 | F27: ='Закупки и склад'!F$20*$C27 -> 0 | G27: ='Закупки и склад'!G$20*$C27 -> 0 | H27: ='Закупки и склад'!H$20*$C27 -> 8800 | I27: ='Закупки и склад'!I$20*$C27 -> 8800 | J27: ='Закупки и склад'!J$20*$C27 -> 8800 | K27: ='Закупки и склад'!K$20*$C27 -> 8800 | L27: ='Закупки и склад'!L$20*$C27 -> 0 | M27: ='Закупки и склад'!M$20*$C27 -> 8800 | ... W27: ='Закупки и склад'!W$20*$C27 -> 8800
A28: Пошлина | B28: ₽ | D28: =SUM(F28:W28) -> 433790 | F28: =SUM(F29:F33) -> 0 | G28: =SUM(G29:G33) -> 0 | H28: =SUM(H29:H33) -> 38630 | I28: =SUM(I29:I33) -> 20310 | J28: =SUM(J29:J33) -> 18320 | K28: =SUM(K29:K33) -> 38630 | L28: =SUM(L29:L33) -> 20310 | M28: =SUM(M29:M33) -> 25190 | ... W28: =SUM(W29:W33) -> 38630
A29: =""&Допущения!$C$38 -> Органайзер в багажник | B29: ₽ | C29: ='Юнит-экономика'!$C$15 -> 67.2 | D29: =SUM(F29:W29) -> 161280 | F29: ='Закупки и склад'!F$16*$C29 -> 0 | G29: ='Закупки и склад'!G$16*$C29 -> 0 | H29: ='Закупки и склад'!H$16*$C29 -> 13440 | I29: ='Закупки и склад'!I$16*$C29 -> 13440 | J29: ='Закупки и склад'!J$16*$C29 -> 0 | K29: ='Закупки и склад'!K$16*$C29 -> 13440 | L29: ='Закупки и склад'!L$16*$C29 -> 13440 | M29: ='Закупки и склад'!M$16*$C29 -> 0 | ... W29: ='Закупки и склад'!W$16*$C29 -> 13440
A30: =""&Допущения!$D$38 -> Автопылесос беспроводной | B30: ₽ | C30: ='Юнит-экономика'!$D$15 -> 45.8 | D30: =SUM(F30:W30) -> 89310 | F30: ='Закупки и склад'!F$17*$C30 -> 0 | G30: ='Закупки и склад'!G$17*$C30 -> 0 | H30: ='Закупки и склад'!H$17*$C30 -> 6870 | I30: ='Закупки и склад'!I$17*$C30 -> 6870 | J30: ='Закупки и склад'!J$17*$C30 -> 0 | K30: ='Закупки и склад'!K$17*$C30 -> 6870 | L30: ='Закупки и склад'!L$17*$C30 -> 6870 | M30: ='Закупки и склад'!M$17*$C30 -> 6870 | ... W30: ='Закупки и склад'!W$17*$C30 -> 6870
A31: =""&Допущения!$E$38 -> Держатель телефона MagSafe | B31: ₽ | C31: ='Юнит-экономика'!$E$15 -> 0 | D31: =SUM(F31:W31) -> 0 | F31: ='Закупки и склад'!F$18*$C31 -> 0 | G31: ='Закупки и склад'!G$18*$C31 -> 0 | H31: ='Закупки и склад'!H$18*$C31 -> 0 | I31: ='Закупки и склад'!I$18*$C31 -> 0 | J31: ='Закупки и склад'!J$18*$C31 -> 0 | K31: ='Закупки и склад'!K$18*$C31 -> 0 | L31: ='Закупки и склад'!L$18*$C31 -> 0 | M31: ='Закупки и склад'!M$18*$C31 -> 0 | ... W31: ='Закупки и склад'!W$18*$C31 -> 0
A32: =""&Допущения!$F$38 -> Чехлы на сиденья, комплект | B32: ₽ | C32: ='Юнит-экономика'!$F$15 -> 183.2 | D32: =SUM(F32:W32) -> 183200 | F32: ='Закупки и склад'!F$19*$C32 -> 0 | G32: ='Закупки и склад'!G$19*$C32 -> 0 | H32: ='Закупки и склад'!H$19*$C32 -> 18320 | I32: ='Закупки и склад'!I$19*$C32 -> 0 | J32: ='Закупки и склад'!J$19*$C32 -> 18320 | K32: ='Закупки и склад'!K$19*$C32 -> 18320 | L32: ='Закупки и склад'!L$19*$C32 -> 0 | M32: ='Закупки и склад'!M$19*$C32 -> 18320 | ... W32: ='Закупки и склад'!W$19*$C32 -> 18320
A33: =""&Допущения!$G$38 -> Видеорегистратор Wi-Fi | B33: ₽ | C33: ='Юнит-экономика'!$G$15 -> 0 | D33: =SUM(F33:W33) -> 0 | F33: ='Закупки и склад'!F$20*$C33 -> 0 | G33: ='Закупки и склад'!G$20*$C33 -> 0 | H33: ='Закупки и склад'!H$20*$C33 -> 0 | I33: ='Закупки и склад'!I$20*$C33 -> 0 | J33: ='Закупки и склад'!J$20*$C33 -> 0 | K33: ='Закупки и склад'!K$20*$C33 -> 0 | L33: ='Закупки и склад'!L$20*$C33 -> 0 | M33: ='Закупки и склад'!M$20*$C33 -> 0 | ... W33: ='Закупки и склад'!W$20*$C33 -> 0
A34: НДС на ввоз | B34: ₽ | D34: =SUM(F34:W34) -> 1968293.8 | F34: =SUM(F35:F39) -> 0 | G34: =SUM(G35:G39) -> 0 | H34: =SUM(H35:H39) -> 158186.6 | I34: =SUM(I35:I39) -> 113852.2 | J34: =SUM(J35:J39) -> 93922.4 | K34: =SUM(K35:K39) -> 136406.6 | L34: =SUM(L35:L39) -> 86044.2 | M34: =SUM(M35:M39) -> 125661.8 | ... W34: =SUM(W35:W39) -> 158186.6
A35: =""&Допущения!$C$38 -> Органайзер в багажник | B35: ₽ | C35: ='Юнит-экономика'!$C$16 -> 162.624 | D35: =SUM(F35:W35) -> 390297.6 | F35: ='Закупки и склад'!F$16*$C35 -> 0 | G35: ='Закупки и склад'!G$16*$C35 -> 0 | H35: ='Закупки и склад'!H$16*$C35 -> 32524.8 | I35: ='Закупки и склад'!I$16*$C35 -> 32524.8 | J35: ='Закупки и склад'!J$16*$C35 -> 0 | K35: ='Закупки и склад'!K$16*$C35 -> 32524.8 | L35: ='Закупки и склад'!L$16*$C35 -> 32524.8 | M35: ='Закупки и склад'!M$16*$C35 -> 0 | ... W35: ='Закупки и склад'!W$16*$C35 -> 32524.8
A36: =""&Допущения!$D$38 -> Автопылесос беспроводной | B36: ₽ | C36: ='Юнит-экономика'!$D$16 -> 211.596 | D36: =SUM(F36:W36) -> 412612.2 | F36: ='Закупки и склад'!F$17*$C36 -> 0 | G36: ='Закупки и склад'!G$17*$C36 -> 0 | H36: ='Закупки и склад'!H$17*$C36 -> 31739.4 | I36: ='Закупки и склад'!I$17*$C36 -> 31739.4 | J36: ='Закупки и склад'!J$17*$C36 -> 0 | K36: ='Закупки и склад'!K$17*$C36 -> 31739.4 | L36: ='Закупки и склад'!L$17*$C36 -> 31739.4 | M36: ='Закупки и склад'!M$17*$C36 -> 31739.4 | ... W36: ='Закупки и склад'!W$17*$C36 -> 31739.4
A37: =""&Допущения!$E$38 -> Держатель телефона MagSafe | B37: ₽ | C37: ='Юнит-экономика'!$E$16 -> 72.6 | D37: =SUM(F37:W37) -> 304920 | F37: ='Закупки и склад'!F$18*$C37 -> 0 | G37: ='Закупки и склад'!G$18*$C37 -> 0 | H37: ='Закупки и склад'!H$18*$C37 -> 21780 | I37: ='Закупки и склад'!I$18*$C37 -> 21780 | J37: ='Закупки и склад'!J$18*$C37 -> 21780 | K37: ='Закупки и склад'!K$18*$C37 -> 0 | L37: ='Закупки и склад'!L$18*$C37 -> 21780 | M37: ='Закупки и склад'!M$18*$C37 -> 21780 | ... W37: ='Закупки и склад'!W$18*$C37 -> 21780
A38: =""&Допущения!$F$38 -> Чехлы на сиденья, комплект | B38: ₽ | C38: ='Юнит-экономика'!$F$16 -> 443.344 | D38: =SUM(F38:W38) -> 443344 | F38: ='Закупки и склад'!F$19*$C38 -> 0 | G38: ='Закупки и склад'!G$19*$C38 -> 0 | H38: ='Закупки и склад'!H$19*$C38 -> 44334.4 | I38: ='Закупки и склад'!I$19*$C38 -> 0 | J38: ='Закупки и склад'!J$19*$C38 -> 44334.4 | K38: ='Закупки и склад'!K$19*$C38 -> 44334.4 | L38: ='Закупки и склад'!L$19*$C38 -> 0 | M38: ='Закупки и склад'!M$19*$C38 -> 44334.4 | ... W38: ='Закупки и склад'!W$19*$C38 -> 44334.4
A39: =""&Допущения!$G$38 -> Видеорегистратор Wi-Fi | B39: ₽ | C39: ='Юнит-экономика'!$G$16 -> 278.08 | D39: =SUM(F39:W39) -> 417120 | F39: ='Закупки и склад'!F$20*$C39 -> 0 | G39: ='Закупки и склад'!G$20*$C39 -> 0 | H39: ='Закупки и склад'!H$20*$C39 -> 27808 | I39: ='Закупки и склад'!I$20*$C39 -> 27808 | J39: ='Закупки и склад'!J$20*$C39 -> 27808 | K39: ='Закупки и склад'!K$20*$C39 -> 27808 | L39: ='Закупки и склад'!L$20*$C39 -> 0 | M39: ='Закупки и склад'!M$20*$C39 -> 27808 | ... W39: ='Закупки и склад'!W$20*$C39 -> 27808
A40: Таможенное оформление | B40: ₽ | D40: =SUM(F40:W40) -> 512000 | F40: =SUM(F41:F45) -> 0 | G40: =SUM(G41:G45) -> 0 | H40: =SUM(H41:H45) -> 40000 | I40: =SUM(I41:I45) -> 32000 | J40: =SUM(J41:J45) -> 24000 | K40: =SUM(K41:K45) -> 32000 | L40: =SUM(L41:L45) -> 24000 | M40: =SUM(M41:M45) -> 32000 | ... W40: =SUM(W41:W45) -> 40000
A41: =""&Допущения!$C$38 -> Органайзер в багажник | B41: ₽ | C41: ='Юнит-экономика'!$C$17 -> 40 | D41: =SUM(F41:W41) -> 96000 | F41: ='Закупки и склад'!F$16*$C41 -> 0 | G41: ='Закупки и склад'!G$16*$C41 -> 0 | H41: ='Закупки и склад'!H$16*$C41 -> 8000 | I41: ='Закупки и склад'!I$16*$C41 -> 8000 | J41: ='Закупки и склад'!J$16*$C41 -> 0 | K41: ='Закупки и склад'!K$16*$C41 -> 8000 | L41: ='Закупки и склад'!L$16*$C41 -> 8000 | M41: ='Закупки и склад'!M$16*$C41 -> 0 | ... W41: ='Закупки и склад'!W$16*$C41 -> 8000
